## 目录
- [异常](#异常)
- [捕获异常](#捕获异常)
- [finally语句](#finally语句)
- [抛出异常](#抛出异常)
- [自定义异常](#自定义异常)
- [NullPointerException空指针异常](#NullPointerException空指针异常)
  - [处理NullPointerException](#处理NullPointerException)
  - [定位NullPointerException](#定位NullPointerException)
  - 






## 异常

Java标准库定义的常用异常包括：

```ascii
Exception
│
├─ RuntimeException
│  │
│  ├─ NullPointerException
│  │
│  ├─ IndexOutOfBoundsException
│  │
│  ├─ SecurityException
│  │
│  └─ IllegalArgumentException
│     │
│     └─ NumberFormatException
│
├─ IOException
│  │
│  ├─ UnsupportedCharsetException
│  │
│  ├─ FileNotFoundException
│  │
│  └─ SocketException
│
├─ ParseException
│
├─ GeneralSecurityException
│
├─ SQLException
│
└─ TimeoutException
```



因为Java的异常是`class`，它的继承关系如下：

```ascii
                     ┌───────────┐
                     │  Object   │
                     └───────────┘
                           ▲
                           │
                     ┌───────────┐
                     │ Throwable │
                     └───────────┘
                           ▲
                 ┌─────────┴─────────┐
                 │                   │
           ┌───────────┐       ┌───────────┐
           │   Error   │       │ Exception │
           └───────────┘       └───────────┘
                 ▲                   ▲
         ┌───────┘              ┌────┴──────────┐
         │                      │               │
┌─────────────────┐    ┌─────────────────┐┌───────────┐
│OutOfMemoryError │... │RuntimeException ││IOException│...
└─────────────────┘    └─────────────────┘└───────────┘
                                ▲
                    ┌───────────┴─────────────┐
                    │                         │
         ┌─────────────────────┐ ┌─────────────────────────┐
         │NullPointerException │ │IllegalArgumentException │...
         └─────────────────────┘ └─────────────────────────┘
```

从继承关系可知：`Throwable`是异常体系的根，它继承自`Object`。`Throwable`有两个体系：`Error`和`Exception`，`Error`表示严重的错误，程序对此一般无能为力，例如：

- `OutOfMemoryError`：内存耗尽
- `NoClassDefFoundError`：无法加载某个Class
- `StackOverflowError`：栈溢出



**而`Exception`则是运行时的错误，它可以被捕获并处理。**

**某些异常是应用程序逻辑处理的一部分，应该捕获并处理。例如：**

- `NumberFormatException`：数值类型的格式错误
- `FileNotFoundException`：未找到文件
- `SocketException`：读取网络失败
- `UnsupportedEncodingException` : 系统不支持GBK编码



**还有一些异常是程序逻辑编写不对造成的，应该修复程序本身。例如：**

- `NullPointerException`：对某个`null`的对象调用方法或字段
- `IndexOutOfBoundsException`：数组索引越界



**`Exception`又分为两大类：**

1. `RuntimeException`以及它的子类；
2. 非`RuntimeException`（包括`IOException`、`ReflectiveOperationException`等等）



Java规定：

- 必须捕获的异常，包括`Exception`及其子类，但不包括`RuntimeException`及其子类，这种类型的异常称为Checked Exception。
- 不需要捕获的异常，包括`Error`及其子类，`RuntimeException`及其子类。
  - 注意：编译器对RuntimeException及其子类不做强制捕获要求，不是指应用程序本身不应该捕获并处理RuntimeException。是否需要捕获，具体问题具体分析。





### 捕获异常

```java
try 
{
  可能会抛出异常的代码段
} 
catch(Exception e)
{
  	处理异常代码
}

 Throwable 相关API:    (这是个类)  import java.lang.Throwable;  Exception 继承于 Throwable
		void  printStackTrace ()
      /* 将 Throwable 对象和栈的轨迹输出到标准错误流。 */
```

```java
/* @ 捕获范例1 */
import java.io.UnsupportedEncodingException;
import java.util.Arrays;

public class tryTest {
    public static void main(String[] args) {
        byte[] bs = toGBK("中文");
        System.out.println(Arrays.toString(bs));
    }

    private static byte[] toGBK(String s) {
        try{
            // 用指定编码转换String为byte[]:
            return s.getBytes("GBK");
        }catch (UnsupportedEncodingException e){
            // 如果系统不支持GBK编码，会捕获到UnsupportedEncodingException:
	          // 如果不捕获UnsupportedEncodingException，会出现编译失败的问题
            System.out.println(e); // 打印异常信息
            e.printStackTrace();  // 所有异常都可以调用该方法打印异常栈，这是一个简单有用的快速打印异常的方法。
            return s.getBytes(); // 尝试使用用默认编码
        }
    }
}

/* 
在方法定义的时候，使用throws Xxx表示该方法可能抛出的异常类型。调用方在调用的时候，必须强制捕获这些异常，否则编译器会报错。
	public byte[] getBytes(String charsetName) throws UnsupportedEncodingException 
  {...}
*/
```



```java
存在多个catch的时候，catch的顺序非常重要：子类必须写在前面。例如：
public static void main(String[] args) {
    try {
        process1();
        process2();
        process3();
    } catch (UnsupportedEncodingException e) {
        System.out.println("Bad encoding");
    } catch (IOException e) {
        System.out.println("IO error");
    }
}
```



```java
捕获多种异常
如果某些异常的处理逻辑相同，但是异常本身不存在继承关系，那么就得编写多条catch子句：
  
public static void main(String[] args) {
    try {
        process1();
        process2();
        process3();
    } catch (IOException | NumberFormatException e) { // IOException或NumberFormatException
      // 因为处理IOException和NumberFormatException的代码是相同的，所以我们可以把它两用|合并到一起
        System.out.println("Bad input");
    } catch (Exception e) {
        System.out.println("Unknown error");
    }
}
```







### finally语句

注意`finally`有几个特点：

1. `finally`语句不是必须的，可写可不写；
2. `finally`总是最后执行。

如果没有发生异常，就正常执行`try { ... }`语句块，然后执行`finally`。如果发生了异常，就中断执行`try { ... }`语句块，然后跳转执行匹配的`catch`语句块，最后执行`finally`。

```java
void process(String file) throws IOException {
    try {
        ...
    } catch (Exception e) {
       ...  
    }
      finally {
        System.out.println("END");  //无论是否出现异常 都会执行。 异常处理完成后也会执行。
    }
}
```

在`catch`中抛出异常，不会影响`finally`的执行。JVM会先执行`finally`，然后抛出异常。

```java
public static void main(String[] args) {
  try {
    Integer.parseInt("abc");
  } catch (Exception e) {
    System.out.println("catched");
    throw new RuntimeException(e);
  } finally {
    System.out.println("finally");
  }
}    

// 上述代码执行结果如下 ，	在catch中抛出异常，不会影响finally的执行。JVM会先执行finally，然后抛出异常。
catched
finally
Exception in thread "main" java.lang.RuntimeException: java.lang.NumberFormatException: For input string: "abc"
    at Main.main(Main.java:8)
Caused by: java.lang.NumberFormatException: For input string: "abc"
    at ...
```



`finally`抛出异常后，原来在`catch`中准备抛出的异常就“消失”了，因为只能抛出一个异常。没有被抛出的异常称为“被屏蔽”的异常（Suppressed Exception）。

在极少数的情况下，我们需要获知所有的异常。如何保存所有的异常信息？方法是先用`origin`变量保存原始异常，然后调用`Throwable.addSuppressed()`，把原始异常添加进来，最后在`finally`抛出：

通过`Throwable.getSuppressed()`可以获取所有的`Suppressed Exception`。

```java
// 当catch和finally都抛出了异常时，虽然catch的异常被屏蔽了，但是，finally抛出的异常仍然包含了它：

public class Main {
    public static void main(String[] args) throws Exception {
        Exception origin = null;
        try {
            System.out.println(Integer.parseInt("abc"));
        } catch (Exception e) {
            origin = e;
            throw e;
        } finally {
            Exception e = new IllegalArgumentException();
            if (origin != null) {
                e.addSuppressed(origin);
            }
            throw e;
        }
    }
}

// 当catch和finally都抛出了异常时，虽然catch的异常被屏蔽了，但是，finally抛出的异常仍然包含了它：
// 输出如下
Exception in thread "main" java.lang.IllegalArgumentException
	at tryTest.tryTest.main(tryTest.java:15)
	Suppressed: java.lang.NumberFormatException: For input string: "abc"
		at java.base/java.lang.NumberFormatException.forInputString(NumberFormatException.java:67)
		at java.base/java.lang.Integer.parseInt(Integer.java:665)
		at java.base/java.lang.Integer.parseInt(Integer.java:781)
		at tryTest.tryTest.main(tryTest.java:10)
```







### 抛出异常

当发生错误时，例如，用户输入了非法的字符，我们就可以抛出异常。

捕获到异常并再次抛出时，一定要留住原始异常，否则很难定位第一案发现场！

如何抛出异常？参考`Integer.parseInt()`方法，抛出异常分两步：

1. 创建某个`Exception`的实例；
2. 用`throw`语句抛出。

下面是一个例子：

```java
void process2(String s) {
    if (s==null) {
        NullPointerException e = new NullPointerException();
        throw e;
      // 或者将上面两行精简为  throw new NullPointerException();
    }
}

当process2()抛出NullPointerException后，被process1()捕获，然后抛出IllegalArgumentException()。
新的异常会丢失原始异常信息，我们已经看不到原始异常 NullPointerException 的信息了。
为了能追踪到完整的异常栈，在构造异常的时候，把原始的 Exception 实例传进去，新的 Exception 就可以持有原始Exception 信息。对上述代码改进如下：

  // 在main()中捕获IllegalArgumentException，我们看看打印的异常栈：
public class Main {
    public static void main(String[] args) {
        try {
            process1();
        } catch (Exception e) {
            e.printStackTrace();
        }
    }

    static void process1() {
        try {
            process2();
        } catch (NullPointerException e) {
            throw new IllegalArgumentException(e);  // 这里将 e 传入了异常类
        }
    }

    static void process2() {
        throw new NullPointerException();
    }
}


/* 输出内容如下
java.lang.IllegalArgumentException: java.lang.NullPointerException
	at tryTest.tryTest.process1(tryTest.java:18)    /// 抛出异常到main
	at tryTest.tryTest.main(tryTest.java:9)         /// 最后收到异常的main
Caused by: java.lang.NullPointerException
	at tryTest.tryTest.process2(tryTest.java:23)    /// 抛出异常到 process1
	at tryTest.tryTest.process1(tryTest.java:16)    /// 这里处理了这个异常，但是代码中又将异常传播
                                                  /// 到 process1() ，所以还应该向上寻找。
	... 1 more
*/
```



### 自定义异常

Java标准库定义的常用异常包括：

```ascii
Exception
│
├─ RuntimeException
│  │
│  ├─ NullPointerException
│  │
│  ├─ IndexOutOfBoundsException
│  │
│  ├─ SecurityException
│  │
│  └─ IllegalArgumentException
│     │
│     └─ NumberFormatException
│
├─ IOException
│  │
│  ├─ UnsupportedCharsetException
│  │
│  ├─ FileNotFoundException
│  │
│  └─ SocketException
│
├─ ParseException
│
├─ GeneralSecurityException
│
├─ SQLException
│
└─ TimeoutException
```



在一个大型项目中，可以自定义新的异常类型，但是，保持一个合理的异常继承体系是非常重要的。

一个常见的做法是自定义一个`BaseException`作为“根异常”，然后，派生出各种业务类型的异常。

`BaseException`需要从一个适合的`Exception`派生，通常建议从`RuntimeException`派生：

```java
public class BaseException extends RuntimeException {
}
```

其他业务类型的异常就可以从`BaseException`派生：

```java
public class UserNotFoundException extends BaseException {
}

public class LoginFailedException extends BaseException {
}

...
```



自定义的`BaseException`应该提供多个构造方法：

```java
public class BaseException extends RuntimeException {
    public BaseException() {
        super();
    }

    public BaseException(String message, Throwable cause) {
        super(message, cause);
    }

    public BaseException(String message) {
        super(message);
    }

    public BaseException(Throwable cause) {
        super(cause);
    }
}
```

上述构造方法实际上都是原样照抄`RuntimeException`。这样，抛出异常的时候，就可以选择合适的构造方法。通过IDE可以根据父类快速生成子类的构造方法。





### NullPointerException空指针异常

`NullPointerException`即空指针异常，俗称NPE。如果一个对象为`null`，调用其方法或访问其字段就会产生`NullPointerException`，这个异常通常是由JVM抛出的，例如：

```java
public class Main {
    public static void main(String[] args) {
        String s = null;
        System.out.println(s.toLowerCase());
    }
}
```



### 处理NullPointerException

严禁使用`catch`来隐藏这种编码错误

- 处理方案:

  - 使用空字符串`""`而不是默认的`null`可避免很多`NullPointerException`，编写业务逻辑时，用空字符串`""`表示未填写比`null`安全得多。

  - 返回空字符串`""`、空数组而不是`null`：

  - 如果调用方一定要根据`null`判断，比如返回`null`表示文件不存在，那么考虑返回`Optional<T>`：

    - ```java
      public Optional<String> readFromFile(String file) {
          if (!fileExist(file)) {
              return Optional.empty();
          }
          ...
      }
      // 这样调用方必须通过Optional.isPresent()判断是否有结果。
      ```





### 定位NullPointerException

```java
public class Main {
    public static void main(String[] args) {
        Person p = new Person();
        System.out.println(p.address.city.toLowerCase());
    }
}

class Person {
    String[] name = new String[2];
    Address address = new Address();
}

class Address {
    String city;
    String street;
    String zipcode;
}

// 输出如下：
Exception in thread "main" java.lang.NullPointerException: Cannot invoke "String.toLowerCase()" because "p.address.city" is null   // 这里体现了null
	at tryTest.tryTest.main(tryTest.java:9)

  
可以在NullPointerException的详细信息中看到类似... because "<local1>.address.city" is null，意思是city字段为null，这样我们就能快速定位问题所在。

这种增强的NullPointerException详细信息是Java 14新增的功能，但默认是关闭的，我们可以给JVM添加一个-XX:+ShowCodeDetailsInExceptionMessages参数启用它：

java -XX:+ShowCodeDetailsInExceptionMessages Main.java
```

